<?xml version="1.0" ?>
<!-- =================================================================================== -->
<!-- |    This document was autogenerated by xacro from minder1_tilted_mounting.urdf.xacro | -->
<!-- |    EDITING THIS FILE BY HAND IS NOT RECOMMENDED                                 | -->
<!-- =================================================================================== -->
<robot name="minder1">
  <link name="base_link">
    <inertial>
      <origin rpy="0 0 0" xyz="-0.235733219546904 0.000233420333349745 -0.303180562170291"/>
      <mass value="118.900127017301"/>
      <inertia ixx="3.77922304668898" ixy="-0.000140085062903995" ixz="0.000279430540132911" iyy="5.74742554699503" iyz="-0.00012063033858365" izz="8.24245009510893"/>
    </inertial>
    <visual>
      <origin rpy="0 0 0" xyz="0 0 0"/>
      <geometry>
        <mesh filename="/home/zheng/Datasets/minder_robot/meshes/minder1/tilted_platform/base_link.STL"/>
      </geometry>
      <material name="">
        <color rgba="0.752941176470588 0.752941176470588 0.752941176470588 1"/>
      </material>
    </visual>
    <collision>
      <origin rpy="0 0 0" xyz="0 0 0"/>
      <geometry>
        <mesh filename="/home/zheng/Datasets/minder_robot/meshes/minder1/tilted_platform/base_link.STL"/>
      </geometry>
    </collision>
  </link>
  <link name="world"/>
  <joint name="world_joint" type="fixed">
    <origin rpy="0 0 0" xyz="0 0 0.786"/>
    <parent link="world"/>
    <child link="base_link"/>
  </joint>
  <link name="Torso_Link">
    <inertial>
      <origin rpy="0 0 0" xyz="0.00707235615624366 -1.85597687055082E-08 0.0748870039317834"/>
      <mass value="2.36175924601202"/>
      <inertia ixx="0.0100070353523762" ixy="2.61612558699609E-09" ixz="0.00163980988491445" iyy="0.011154883266814" iyz="4.30877557158066E-10" izz="0.00933985716896608"/>
    </inertial>
    <visual>
      <origin rpy="0 0 0" xyz="0 0 0"/>
      <geometry>
        <mesh filename="/home/zheng/Datasets/minder_robot/meshes/minder1/tilted_platform/Torso_Link.STL"/>
      </geometry>
      <material name="">
        <color rgba="0.752941176470588 0.752941176470588 0.752941176470588 1"/>
      </material>
    </visual>
    <collision>
      <origin rpy="0 0 0" xyz="0 0 0"/>
      <geometry>
        <mesh filename="/home/zheng/Datasets/minder_robot/meshes/minder1/tilted_platform/Torso_Link.STL"/>
      </geometry>
    </collision>
  </link>
  <joint name="Torso_Joint" type="fixed">
    <origin rpy="0 0 0" xyz="0 0 0"/>
    <parent link="base_link"/>
    <child link="Torso_Link"/>
    <axis xyz="0 0 0"/>
  </joint>
  <!-- safety_distance: Minimum safety distance in [m] by which the collision volumes are expanded and which is enforced during robot motions -->
  <!-- arm_id: Namespace of the robot arm. Serves to differentiate between arms in case of multiple instances. -->
  <!-- joint_limits: description of the joint limits that comes from a YAML file. Example definition: ${xacro.load_yaml('$(find minder1_description)/robots/fr3/joint_limits.yaml')} -->
  <!-- kinematics: description of the kinematics that comes from a YAML file. Example definition: ${xacro.load_yaml('$(find minder1_description)/robots/fr3/kinematics.yaml')} -->
  <!-- inertials: description of the inertials that comes from a YAML file. Example definition: ${xacro.load_yaml('$(find minder1_description)/robots/fr3/inertials.yaml')} -->
  <!-- dynamics: description of the dynamics that comes from a YAML file. Example definition: ${xacro.load_yaml('$(find minder1_description)/robots/fr3/dynamics.yaml')} -->
  <joint name="Torso_Link_left_arm_joint" type="fixed">
    <parent link="Torso_Link"/>
    <child link="left_arm_link0"/>
    <origin rpy="-1.3685242 0.91321796 -0.61683434" xyz="0.02713 0.07009 0.5"/>
  </joint>
  <link name="left_arm_link0">
    <visual name="left_arm_link0_visual">
      <geometry>
        <mesh filename="/home/zheng/Datasets/minder_robot/meshes/robot_arms/fr3/visual/link0.dae"/>
      </geometry>
    </visual>
    <collision name="left_arm_link0_collision">
      <geometry>
        <mesh filename="/home/zheng/Datasets/minder_robot/meshes/robot_arms/fr3/collision/link0.stl"/>
      </geometry>
    </collision>
    <inertial>
      <origin rpy="0 0 0" xyz="-0.0172 0.0004 0.0745"/>
      <mass value="2.3966"/>
      <inertia ixx="0.009" ixy="0.0" ixz="0.002" iyy="0.0115" iyz="0.0" izz="0.0085"/>
    </inertial>
  </link>
  <link name="left_arm_link1">
    <visual name="left_arm_link1_visual">
      <geometry>
        <mesh filename="/home/zheng/Datasets/minder_robot/meshes/robot_arms/fr3/visual/link1.dae"/>
      </geometry>
    </visual>
    <collision name="left_arm_link1_collision">
      <geometry>
        <mesh filename="/home/zheng/Datasets/minder_robot/meshes/robot_arms/fr3/collision/link1.stl"/>
      </geometry>
    </collision>
    <inertial>
      <origin rpy="0 0 0" xyz="0.0000004128 -0.0181251324 -0.0386035970"/>
      <mass value="2.9274653454"/>
      <inertia ixx="0.023927316485107913" ixy="1.3317903455714081e-05" ixz="-0.00011404774918616684" iyy="0.0224821613275756" iyz="-0.0019950320628240115" izz="0.006350098258530016"/>
    </inertial>
  </link>
  <joint name="left_arm_joint1" type="revolute">
    <origin rpy="0 0 0" xyz="0 0 0.333"/>
    <parent link="left_arm_link0"/>
    <child link="left_arm_link1"/>
    <axis xyz="0 0 1"/>
    <limit effort="87.0" lower="-2.7437" upper="2.7437" velocity="2.62"/>
    <dynamics D="1" K="7000" damping="0.003" mu_coulomb="0" mu_viscous="16"/>
  </joint>
  <link name="left_arm_link2">
    <visual name="left_arm_link2_visual">
      <geometry>
        <mesh filename="/home/zheng/Datasets/minder_robot/meshes/robot_arms/fr3/visual/link2.dae"/>
      </geometry>
    </visual>
    <collision name="left_arm_link2_collision">
      <geometry>
        <mesh filename="/home/zheng/Datasets/minder_robot/meshes/robot_arms/fr3/collision/link2.stl"/>
      </geometry>
    </collision>
    <inertial>
      <origin rpy="0 0 0" xyz="0.0031828864 -0.0743221644 0.0088146084"/>
      <mass value="2.9355370338"/>
      <inertia ixx="0.041938946257609425" ixy="0.00020257331521090626" ixz="0.004077784227179924" iyy="0.02514514885014724" iyz="-0.0042252158006570156" izz="0.06170214472888839"/>
    </inertial>
  </link>
  <joint name="left_arm_joint2" type="revolute">
    <origin rpy="-1.570796326794897 0 0" xyz="0 0 0"/>
    <parent link="left_arm_link1"/>
    <child link="left_arm_link2"/>
    <axis xyz="0 0 1"/>
    <limit effort="87.0" lower="-1.7837" upper="1.7837" velocity="2.62"/>
    <dynamics D="1" K="7000" damping="0.003" mu_coulomb="0" mu_viscous="16"/>
  </joint>
  <link name="left_arm_link3">
    <visual name="left_arm_link3_visual">
      <geometry>
        <mesh filename="/home/zheng/Datasets/minder_robot/meshes/robot_arms/fr3/visual/link3.dae"/>
      </geometry>
    </visual>
    <collision name="left_arm_link3_collision">
      <geometry>
        <mesh filename="/home/zheng/Datasets/minder_robot/meshes/robot_arms/fr3/collision/link3.stl"/>
      </geometry>
    </collision>
    <inertial>
      <origin rpy="0 0 0" xyz="0.0407015686 -0.0048200565 -0.0289730823"/>
      <mass value="2.2449013699"/>
      <inertia ixx="0.02410142547240885" ixy="0.002404694559042109" ixz="-0.002856269270114313" iyy="0.01974053266708178" iyz="-0.002104212683891874" izz="0.019044494482244823"/>
    </inertial>
  </link>
  <joint name="left_arm_joint3" type="revolute">
    <origin rpy="1.570796326794897 0 0" xyz="0 -0.316 0"/>
    <parent link="left_arm_link2"/>
    <child link="left_arm_link3"/>
    <axis xyz="0 0 1"/>
    <limit effort="87.0" lower="-2.9007" upper="2.9007" velocity="2.62"/>
    <dynamics D="1" K="7000" damping="0.003" mu_coulomb="0" mu_viscous="16"/>
  </joint>
  <link name="left_arm_link4">
    <visual name="left_arm_link4_visual">
      <geometry>
        <mesh filename="/home/zheng/Datasets/minder_robot/meshes/robot_arms/fr3/visual/link4.dae"/>
      </geometry>
    </visual>
    <collision name="left_arm_link4_collision">
      <geometry>
        <mesh filename="/home/zheng/Datasets/minder_robot/meshes/robot_arms/fr3/collision/link4.stl"/>
      </geometry>
    </collision>
    <inertial>
      <origin rpy="0 0 0" xyz="-0.0459100965 0.0630492960 -0.0085187868"/>
      <mass value="2.6155955791"/>
      <inertia ixx="0.03452998321913202" ixy="0.01322552265982813" ixz="0.01015142998484113" iyy="0.028881621933049058" iyz="-0.0009762833870704552" izz="0.04125471171146641"/>
    </inertial>
  </link>
  <joint name="left_arm_joint4" type="revolute">
    <origin rpy="1.570796326794897 0 0" xyz="0.0825 0 0"/>
    <parent link="left_arm_link3"/>
    <child link="left_arm_link4"/>
    <axis xyz="0 0 1"/>
    <limit effort="87.0" lower="-3.0421" upper="-0.1518" velocity="2.62"/>
    <dynamics D="1" K="7000" damping="0.003" mu_coulomb="0" mu_viscous="16"/>
  </joint>
  <link name="left_arm_link5">
    <visual name="left_arm_link5_visual">
      <geometry>
        <mesh filename="/home/zheng/Datasets/minder_robot/meshes/robot_arms/fr3/visual/link5.dae"/>
      </geometry>
    </visual>
    <collision name="left_arm_link5_collision">
      <geometry>
        <mesh filename="/home/zheng/Datasets/minder_robot/meshes/robot_arms/fr3/collision/link5.stl"/>
      </geometry>
    </collision>
    <inertial>
      <origin rpy="0 0 0" xyz="-0.0016039605 0.0292536262 -0.0972965990"/>
      <mass value="2.3271207594"/>
      <inertia ixx="0.051610278463662895" ixy="-0.005715173387783472" ixz="-0.0035673167625872135" iyy="0.04787729713371481" iyz="0.010673985108535986" izz="0.016423625579357254"/>
    </inertial>
  </link>
  <joint name="left_arm_joint5" type="revolute">
    <origin rpy="-1.570796326794897 0 0" xyz="-0.0825 0.384 0"/>
    <parent link="left_arm_link4"/>
    <child link="left_arm_link5"/>
    <axis xyz="0 0 1"/>
    <limit effort="12.0" lower="-2.8065" upper="2.8065" velocity="5.26"/>
    <dynamics D="1" K="7000" damping="0.003" mu_coulomb="0" mu_viscous="16"/>
  </joint>
  <link name="left_arm_link6">
    <visual name="left_arm_link6_visual">
      <geometry>
        <mesh filename="/home/zheng/Datasets/minder_robot/meshes/robot_arms/fr3/visual/link6.dae"/>
      </geometry>
    </visual>
    <collision name="left_arm_link6_collision">
      <geometry>
        <mesh filename="/home/zheng/Datasets/minder_robot/meshes/robot_arms/fr3/collision/link6.stl"/>
      </geometry>
    </collision>
    <inertial>
      <origin rpy="0 0 0" xyz="0.0597131221 -0.0410294666 -0.0101692726"/>
      <mass value="1.8170376524"/>
      <inertia ixx="0.005412333594383447" ixy="0.006193456360285834" ixz="0.0014219289306117652" iyy="0.014058329545509979" iyz="-0.0013140753741120031" izz="0.016080817924212554"/>
    </inertial>
  </link>
  <joint name="left_arm_joint6" type="revolute">
    <origin rpy="1.570796326794897 0 0" xyz="0 0 0"/>
    <parent link="left_arm_link5"/>
    <child link="left_arm_link6"/>
    <axis xyz="0 0 1"/>
    <limit effort="12.0" lower="0.5445" upper="4.5169" velocity="4.18"/>
    <dynamics D="1" K="7000" damping="0.003" mu_coulomb="0" mu_viscous="16"/>
  </joint>
  <link name="left_arm_link7">
    <visual name="left_arm_link7_visual">
      <geometry>
        <mesh filename="/home/zheng/Datasets/minder_robot/meshes/robot_arms/fr3/visual/link7.dae"/>
      </geometry>
    </visual>
    <collision name="left_arm_link7_collision">
      <geometry>
        <mesh filename="/home/zheng/Datasets/minder_robot/meshes/robot_arms/fr3/collision/link7.stl"/>
      </geometry>
    </collision>
    <inertial>
      <origin rpy="0 0 0" xyz="0.0045225817 0.0086261921 -0.0161633251"/>
      <mass value="0.6271432862"/>
      <inertia ixx="0.00021092389150104718" ixy="-2.433299114461931e-05" ixz="4.564480393778983e-05" iyy="0.00017718568002411474" iyz="8.744070223226438e-05" izz="5.993190599659971e-05"/>
    </inertial>
  </link>
  <joint name="left_arm_joint7" type="revolute">
    <origin rpy="1.570796326794897 0 0" xyz="0.088 0 0"/>
    <parent link="left_arm_link6"/>
    <child link="left_arm_link7"/>
    <axis xyz="0 0 1"/>
    <limit effort="12.0" lower="-3.0159" upper="3.0159" velocity="5.26"/>
    <dynamics D="1" K="7000" damping="0.003" mu_coulomb="0" mu_viscous="16"/>
  </joint>
  <link name="left_arm_link8"/>
  <joint name="left_arm_joint8" type="fixed">
    <origin rpy="0 0 0" xyz="0 0 0.107"/>
    <parent link="left_arm_link7"/>
    <child link="left_arm_link8"/>
  </joint>
  <link name="left_arm_link9"/>
  <joint name="left_arm_joint9" type="fixed">
    <origin rpy="0 0 -0.7853981634" xyz="0 0 0"/>
    <parent link="left_arm_link8"/>
    <child link="left_arm_link9"/>
  </joint>
  <joint name="left_arm_hand_joint" type="fixed">
    <parent link="left_arm_link9"/>
    <child link="left_arm_hand"/>
    <origin rpy="0 0 0" xyz="0 0 0"/>
  </joint>
  <link name="left_arm_hand">
    <visual name="left_arm_hand_visual">
      <geometry>
        <mesh filename="/home/zheng/Datasets/minder_robot/meshes/robot_ee/franka_hand_white/visual/hand.dae"/>
      </geometry>
    </visual>
    <collision name="left_arm_hand_collision">
      <geometry>
        <mesh filename="/home/zheng/Datasets/minder_robot/meshes/robot_ee/franka_hand_white/collision/hand.stl"/>
      </geometry>
    </collision>
  </link>
  <!-- Define the hand_tcp frame -->
  <link name="left_arm_hand_tcp"/>
  <joint name="left_arm_hand_tcp_joint" type="fixed">
    <origin rpy="0 0 0" xyz="0 0 0.1034"/>
    <parent link="left_arm_hand"/>
    <child link="left_arm_hand_tcp"/>
  </joint>
  <!-- Franka Hand with UMI type fingers -->
  <link name="left_arm_leftfinger">
    <visual name="left_arm_leftfinger_visual">
      <geometry>
        <mesh filename="/home/zheng/Datasets/minder_robot/meshes/robot_ee/franka_hand_white/visual/umi_finger.dae"/>
      </geometry>
    </visual>
    <collision>
      <geometry>
        <mesh filename="/home/zheng/Datasets/minder_robot/meshes/robot_ee/franka_hand_white/collision/umi_finger.stl"/>
      </geometry>
    </collision>
  </link>
  <link name="left_arm_rightfinger">
    <visual name="left_arm_rightfinger_visual">
      <origin rpy="0 0 3.141592653589793" xyz="0 0 0"/>
      <geometry>
        <mesh filename="/home/zheng/Datasets/minder_robot/meshes/robot_ee/franka_hand_white/visual/umi_finger.dae"/>
      </geometry>
    </visual>
    <collision>
      <origin rpy="0 0 3.141592653589793" xyz="0 0 0"/>
      <geometry>
        <mesh filename="/home/zheng/Datasets/minder_robot/meshes/robot_ee/franka_hand_white/collision/umi_finger.stl"/>
      </geometry>
    </collision>
  </link>
  <joint name="left_arm_finger_joint1" type="prismatic">
    <parent link="left_arm_hand"/>
    <child link="left_arm_leftfinger"/>
    <origin rpy="0 0 0" xyz="0 0 0.0584"/>
    <axis xyz="0 1 0"/>
    <limit effort="100" lower="0.0" upper="0.04" velocity="0.2"/>
    <dynamics damping="0.3"/>
  </joint>
  <joint name="left_arm_finger_joint2" type="prismatic">
    <parent link="left_arm_hand"/>
    <child link="left_arm_rightfinger"/>
    <origin rpy="0 0 0" xyz="0 0 0.0584"/>
    <axis xyz="0 -1 0"/>
    <limit effort="100" lower="0.0" upper="0.04" velocity="0.2"/>
    <mimic joint="left_arm_finger_joint1"/>
    <dynamics damping="0.3"/>
  </joint>
  <!-- safety_distance: Minimum safety distance in [m] by which the collision volumes are expanded and which is enforced during robot motions -->
  <!-- arm_id: Namespace of the robot arm. Serves to differentiate between arms in case of multiple instances. -->
  <!-- joint_limits: description of the joint limits that comes from a YAML file. Example definition: ${xacro.load_yaml('$(find minder1_description)/robots/fr3/joint_limits.yaml')} -->
  <!-- kinematics: description of the kinematics that comes from a YAML file. Example definition: ${xacro.load_yaml('$(find minder1_description)/robots/fr3/kinematics.yaml')} -->
  <!-- inertials: description of the inertials that comes from a YAML file. Example definition: ${xacro.load_yaml('$(find minder1_description)/robots/fr3/inertials.yaml')} -->
  <!-- dynamics: description of the dynamics that comes from a YAML file. Example definition: ${xacro.load_yaml('$(find minder1_description)/robots/fr3/dynamics.yaml')} -->
  <joint name="Torso_Link_right_arm_joint" type="fixed">
    <parent link="Torso_Link"/>
    <child link="right_arm_link0"/>
    <origin rpy="1.3685242 0.91321796 0.61683434" xyz="0.02713 -0.07009 0.5"/>
  </joint>
  <link name="right_arm_link0">
    <visual name="right_arm_link0_visual">
      <geometry>
        <mesh filename="/home/zheng/Datasets/minder_robot/meshes/robot_arms/fr3/visual/link0.dae"/>
      </geometry>
    </visual>
    <collision name="right_arm_link0_collision">
      <geometry>
        <mesh filename="/home/zheng/Datasets/minder_robot/meshes/robot_arms/fr3/collision/link0.stl"/>
      </geometry>
    </collision>
    <inertial>
      <origin rpy="0 0 0" xyz="-0.0172 0.0004 0.0745"/>
      <mass value="2.3966"/>
      <inertia ixx="0.009" ixy="0.0" ixz="0.002" iyy="0.0115" iyz="0.0" izz="0.0085"/>
    </inertial>
  </link>
  <link name="right_arm_link1">
    <visual name="right_arm_link1_visual">
      <geometry>
        <mesh filename="/home/zheng/Datasets/minder_robot/meshes/robot_arms/fr3/visual/link1.dae"/>
      </geometry>
    </visual>
    <collision name="right_arm_link1_collision">
      <geometry>
        <mesh filename="/home/zheng/Datasets/minder_robot/meshes/robot_arms/fr3/collision/link1.stl"/>
      </geometry>
    </collision>
    <inertial>
      <origin rpy="0 0 0" xyz="0.0000004128 -0.0181251324 -0.0386035970"/>
      <mass value="2.9274653454"/>
      <inertia ixx="0.023927316485107913" ixy="1.3317903455714081e-05" ixz="-0.00011404774918616684" iyy="0.0224821613275756" iyz="-0.0019950320628240115" izz="0.006350098258530016"/>
    </inertial>
  </link>
  <joint name="right_arm_joint1" type="revolute">
    <origin rpy="0 0 0" xyz="0 0 0.333"/>
    <parent link="right_arm_link0"/>
    <child link="right_arm_link1"/>
    <axis xyz="0 0 1"/>
    <limit effort="87.0" lower="-2.7437" upper="2.7437" velocity="2.62"/>
    <dynamics D="1" K="7000" damping="0.003" mu_coulomb="0" mu_viscous="16"/>
  </joint>
  <link name="right_arm_link2">
    <visual name="right_arm_link2_visual">
      <geometry>
        <mesh filename="/home/zheng/Datasets/minder_robot/meshes/robot_arms/fr3/visual/link2.dae"/>
      </geometry>
    </visual>
    <collision name="right_arm_link2_collision">
      <geometry>
        <mesh filename="/home/zheng/Datasets/minder_robot/meshes/robot_arms/fr3/collision/link2.stl"/>
      </geometry>
    </collision>
    <inertial>
      <origin rpy="0 0 0" xyz="0.0031828864 -0.0743221644 0.0088146084"/>
      <mass value="2.9355370338"/>
      <inertia ixx="0.041938946257609425" ixy="0.00020257331521090626" ixz="0.004077784227179924" iyy="0.02514514885014724" iyz="-0.0042252158006570156" izz="0.06170214472888839"/>
    </inertial>
  </link>
  <joint name="right_arm_joint2" type="revolute">
    <origin rpy="-1.570796326794897 0 0" xyz="0 0 0"/>
    <parent link="right_arm_link1"/>
    <child link="right_arm_link2"/>
    <axis xyz="0 0 1"/>
    <limit effort="87.0" lower="-1.7837" upper="1.7837" velocity="2.62"/>
    <dynamics D="1" K="7000" damping="0.003" mu_coulomb="0" mu_viscous="16"/>
  </joint>
  <link name="right_arm_link3">
    <visual name="right_arm_link3_visual">
      <geometry>
        <mesh filename="/home/zheng/Datasets/minder_robot/meshes/robot_arms/fr3/visual/link3.dae"/>
      </geometry>
    </visual>
    <collision name="right_arm_link3_collision">
      <geometry>
        <mesh filename="/home/zheng/Datasets/minder_robot/meshes/robot_arms/fr3/collision/link3.stl"/>
      </geometry>
    </collision>
    <inertial>
      <origin rpy="0 0 0" xyz="0.0407015686 -0.0048200565 -0.0289730823"/>
      <mass value="2.2449013699"/>
      <inertia ixx="0.02410142547240885" ixy="0.002404694559042109" ixz="-0.002856269270114313" iyy="0.01974053266708178" iyz="-0.002104212683891874" izz="0.019044494482244823"/>
    </inertial>
  </link>
  <joint name="right_arm_joint3" type="revolute">
    <origin rpy="1.570796326794897 0 0" xyz="0 -0.316 0"/>
    <parent link="right_arm_link2"/>
    <child link="right_arm_link3"/>
    <axis xyz="0 0 1"/>
    <limit effort="87.0" lower="-2.9007" upper="2.9007" velocity="2.62"/>
    <dynamics D="1" K="7000" damping="0.003" mu_coulomb="0" mu_viscous="16"/>
  </joint>
  <link name="right_arm_link4">
    <visual name="right_arm_link4_visual">
      <geometry>
        <mesh filename="/home/zheng/Datasets/minder_robot/meshes/robot_arms/fr3/visual/link4.dae"/>
      </geometry>
    </visual>
    <collision name="right_arm_link4_collision">
      <geometry>
        <mesh filename="/home/zheng/Datasets/minder_robot/meshes/robot_arms/fr3/collision/link4.stl"/>
      </geometry>
    </collision>
    <inertial>
      <origin rpy="0 0 0" xyz="-0.0459100965 0.0630492960 -0.0085187868"/>
      <mass value="2.6155955791"/>
      <inertia ixx="0.03452998321913202" ixy="0.01322552265982813" ixz="0.01015142998484113" iyy="0.028881621933049058" iyz="-0.0009762833870704552" izz="0.04125471171146641"/>
    </inertial>
  </link>
  <joint name="right_arm_joint4" type="revolute">
    <origin rpy="1.570796326794897 0 0" xyz="0.0825 0 0"/>
    <parent link="right_arm_link3"/>
    <child link="right_arm_link4"/>
    <axis xyz="0 0 1"/>
    <limit effort="87.0" lower="-3.0421" upper="-0.1518" velocity="2.62"/>
    <dynamics D="1" K="7000" damping="0.003" mu_coulomb="0" mu_viscous="16"/>
  </joint>
  <link name="right_arm_link5">
    <visual name="right_arm_link5_visual">
      <geometry>
        <mesh filename="/home/zheng/Datasets/minder_robot/meshes/robot_arms/fr3/visual/link5.dae"/>
      </geometry>
    </visual>
    <collision name="right_arm_link5_collision">
      <geometry>
        <mesh filename="/home/zheng/Datasets/minder_robot/meshes/robot_arms/fr3/collision/link5.stl"/>
      </geometry>
    </collision>
    <inertial>
      <origin rpy="0 0 0" xyz="-0.0016039605 0.0292536262 -0.0972965990"/>
      <mass value="2.3271207594"/>
      <inertia ixx="0.051610278463662895" ixy="-0.005715173387783472" ixz="-0.0035673167625872135" iyy="0.04787729713371481" iyz="0.010673985108535986" izz="0.016423625579357254"/>
    </inertial>
  </link>
  <joint name="right_arm_joint5" type="revolute">
    <origin rpy="-1.570796326794897 0 0" xyz="-0.0825 0.384 0"/>
    <parent link="right_arm_link4"/>
    <child link="right_arm_link5"/>
    <axis xyz="0 0 1"/>
    <limit effort="12.0" lower="-2.8065" upper="2.8065" velocity="5.26"/>
    <dynamics D="1" K="7000" damping="0.003" mu_coulomb="0" mu_viscous="16"/>
  </joint>
  <link name="right_arm_link6">
    <visual name="right_arm_link6_visual">
      <geometry>
        <mesh filename="/home/zheng/Datasets/minder_robot/meshes/robot_arms/fr3/visual/link6.dae"/>
      </geometry>
    </visual>
    <collision name="right_arm_link6_collision">
      <geometry>
        <mesh filename="/home/zheng/Datasets/minder_robot/meshes/robot_arms/fr3/collision/link6.stl"/>
      </geometry>
    </collision>
    <inertial>
      <origin rpy="0 0 0" xyz="0.0597131221 -0.0410294666 -0.0101692726"/>
      <mass value="1.8170376524"/>
      <inertia ixx="0.005412333594383447" ixy="0.006193456360285834" ixz="0.0014219289306117652" iyy="0.014058329545509979" iyz="-0.0013140753741120031" izz="0.016080817924212554"/>
    </inertial>
  </link>
  <joint name="right_arm_joint6" type="revolute">
    <origin rpy="1.570796326794897 0 0" xyz="0 0 0"/>
    <parent link="right_arm_link5"/>
    <child link="right_arm_link6"/>
    <axis xyz="0 0 1"/>
    <limit effort="12.0" lower="0.5445" upper="4.5169" velocity="4.18"/>
    <dynamics D="1" K="7000" damping="0.003" mu_coulomb="0" mu_viscous="16"/>
  </joint>
  <link name="right_arm_link7">
    <visual name="right_arm_link7_visual">
      <geometry>
        <mesh filename="/home/zheng/Datasets/minder_robot/meshes/robot_arms/fr3/visual/link7.dae"/>
      </geometry>
    </visual>
    <collision name="right_arm_link7_collision">
      <geometry>
        <mesh filename="/home/zheng/Datasets/minder_robot/meshes/robot_arms/fr3/collision/link7.stl"/>
      </geometry>
    </collision>
    <inertial>
      <origin rpy="0 0 0" xyz="0.0045225817 0.0086261921 -0.0161633251"/>
      <mass value="0.6271432862"/>
      <inertia ixx="0.00021092389150104718" ixy="-2.433299114461931e-05" ixz="4.564480393778983e-05" iyy="0.00017718568002411474" iyz="8.744070223226438e-05" izz="5.993190599659971e-05"/>
    </inertial>
  </link>
  <joint name="right_arm_joint7" type="revolute">
    <origin rpy="1.570796326794897 0 0" xyz="0.088 0 0"/>
    <parent link="right_arm_link6"/>
    <child link="right_arm_link7"/>
    <axis xyz="0 0 1"/>
    <limit effort="12.0" lower="-3.0159" upper="3.0159" velocity="5.26"/>
    <dynamics D="1" K="7000" damping="0.003" mu_coulomb="0" mu_viscous="16"/>
  </joint>
  <link name="right_arm_link8"/>
  <joint name="right_arm_joint8" type="fixed">
    <origin rpy="0 0 0" xyz="0 0 0.107"/>
    <parent link="right_arm_link7"/>
    <child link="right_arm_link8"/>
  </joint>
  <link name="right_arm_link9"/>
  <joint name="right_arm_joint9" type="fixed">
    <origin rpy="0 0 -0.7853981634" xyz="0 0 0"/>
    <parent link="right_arm_link8"/>
    <child link="right_arm_link9"/>
  </joint>
  <joint name="right_arm_hand_joint" type="fixed">
    <parent link="right_arm_link9"/>
    <child link="right_arm_hand"/>
    <origin rpy="0 0 0" xyz="0 0 0"/>
  </joint>
  <link name="right_arm_hand">
    <visual name="right_arm_hand_visual">
      <geometry>
        <mesh filename="/home/zheng/Datasets/minder_robot/meshes/robot_ee/franka_hand_white/visual/hand.dae"/>
      </geometry>
    </visual>
    <collision name="right_arm_hand_collision">
      <geometry>
        <mesh filename="/home/zheng/Datasets/minder_robot/meshes/robot_ee/franka_hand_white/collision/hand.stl"/>
      </geometry>
    </collision>
  </link>
  <!-- Define the hand_tcp frame -->
  <link name="right_arm_hand_tcp"/>
  <joint name="right_arm_hand_tcp_joint" type="fixed">
    <origin rpy="0 0 0" xyz="0 0 0.1034"/>
    <parent link="right_arm_hand"/>
    <child link="right_arm_hand_tcp"/>
  </joint>
  <!-- Franka Hand with UMI type fingers -->
  <link name="right_arm_leftfinger">
    <visual name="right_arm_leftfinger_visual">
      <geometry>
        <mesh filename="/home/zheng/Datasets/minder_robot/meshes/robot_ee/franka_hand_white/visual/umi_finger.dae"/>
      </geometry>
    </visual>
    <collision>
      <geometry>
        <mesh filename="/home/zheng/Datasets/minder_robot/meshes/robot_ee/franka_hand_white/collision/umi_finger.stl"/>
      </geometry>
    </collision>
  </link>
  <link name="right_arm_rightfinger">
    <visual name="right_arm_rightfinger_visual">
      <origin rpy="0 0 3.141592653589793" xyz="0 0 0"/>
      <geometry>
        <mesh filename="/home/zheng/Datasets/minder_robot/meshes/robot_ee/franka_hand_white/visual/umi_finger.dae"/>
      </geometry>
    </visual>
    <collision>
      <origin rpy="0 0 3.141592653589793" xyz="0 0 0"/>
      <geometry>
        <mesh filename="/home/zheng/Datasets/minder_robot/meshes/robot_ee/franka_hand_white/collision/umi_finger.stl"/>
      </geometry>
    </collision>
  </link>
  <joint name="right_arm_finger_joint1" type="prismatic">
    <parent link="right_arm_hand"/>
    <child link="right_arm_leftfinger"/>
    <origin rpy="0 0 0" xyz="0 0 0.0584"/>
    <axis xyz="0 1 0"/>
    <limit effort="100" lower="0.0" upper="0.04" velocity="0.2"/>
    <dynamics damping="0.3"/>
  </joint>
  <joint name="right_arm_finger_joint2" type="prismatic">
    <parent link="right_arm_hand"/>
    <child link="right_arm_rightfinger"/>
    <origin rpy="0 0 0" xyz="0 0 0.0584"/>
    <axis xyz="0 -1 0"/>
    <limit effort="100" lower="0.0" upper="0.04" velocity="0.2"/>
    <mimic joint="right_arm_finger_joint1"/>
    <dynamics damping="0.3"/>
  </joint>
</robot>
